<div align="center" id="top"> 
  &#xa0;
</div>

<h1 align="center">3. Error handing and Promise</h1>

<br>

## Error handling

เป็นการจัดการ error ที่เราคาดการไว้ทั้งที่ตั้งใจและไม่ตั้งใจก็ตาม

<br>

- The "try…catch" syntax

```javascript
try {
  // code...
} catch (err) {
  // error handling
}
```

<br>

- try...catch มีลำดับการทำงานดังนี้
  - executed code ที่อยู่ภายใน `try`
  - ถ้าไม่มี error จะมองข้าม `catch` แต่ถ้ามี error จะเข้าไปทำงานใน `catch`

  ![object](./images/error_handing.PNG)

<br>

- ry…catch…finally

สามารถทำงานได้หลังจากที่ทำงาน `catch` เสร็จแล้ว หรือไม่ต้องทำงาน `catch` กล่าวคือจะทำงานหลังจาก executed code ในส่วนที่ต้องการเสร็จแล้ว


```javascript
try {
   ... try to execute the code ...
} catch(e) {
   ... handle errors ...
} finally {
   ... execute always ...
}
```

<br>

## Promises

เป็นการเพิ่มความสามารถในการทำงานของ JavaScript ให้ทำงานแบบ asynchronous โดยการใช้ Promise เป็นผู้ช่วย

```javascript
let promise = new Promise(function(resolve, reject) {
  // executor (the producing code, "singer")
});
```

![object](./images/promise.PNG)

<br>

<br>

- than

เป็น callback function ที่จะทำงานต่อจากคำสั่งก่อนหน้า อาจจะเป็นต่อจาก Promise หรือ then ก่อนหน้าก็ได้(ทำเป็น chain method)

![object](./images/promise_than.PNG)

```javascript
let promise = new Promise(function(resolve, reject) {
  setTimeout(() => resolve("done!"), 1000);
});

promise.then(
  result => console.log(result),  // shows "done!" after 1 second
  error => console.log(error)     // doesn't run
);
```

<br>

```javascript
new Promise(function(resolve, reject) {
  setTimeout(() => resolve(1), 1000);
}).then(function(result) {
  console.log(result); // 1
  return new Promise((resolve, reject) => { // (*)
    setTimeout(() => resolve(result * 2), 1000);
  });
}).then(function(result) { // (**)
  console.log(result); // 2
  return new Promise((resolve, reject) => {
    setTimeout(() => resolve(result * 2), 1000);
  });
}).then(function(result) {
  console.log(result); // 4
});
```

<br>

- catch

เป็น callback function จะทำงานถ้าได้ error จาก Promise

```javascript
let promise = new Promise((resolve, reject) => {
  setTimeout(() => reject(new Error("Whoops!")), 1000);
});

// .catch(f) is the same as promise.then(null, f)
promise.catch(alert); // shows "Error: Whoops!" after 1 second
```

<br>

- finally

```javascript
new Promise((resolve, reject) => {
  setTimeout(() => resolve("result"), 2000)
})
.finally(() => console.log("Promise ready"))
.then(result => console.log(result)); // <-- .then handles the result
```

<br>

```javascript
new Promise((resolve, reject) => {
  throw new Error("error");
})
.finally(() => console.log("Promise ready"))
.catch(err => console.log(err));  // <-- .catch handles the error object
```

<br>

## Async/await

- Async function

`async` เป็น keyword ที่ใส่ไว้หน้า function เพื่อให้ function returns เป็น Promise เพื่อให้ทำงานแบบ asynchronous ได้

```javascript
async function f() {
  return 1;
}
f().then(alert); // 1
```

<br>

- Await

ใช้สำหรับรอให้ Promise function ทำงานจนเสร็จ

```javascript
async function f() {
  let promise = new Promise((resolve, reject) => {
    setTimeout(() => resolve("done!"), 1000)
  });

  let result = await promise; // wait until the promise resolves (*)
  alert(result); // "done!"
}
f();
```

<br>

---

<br>

## License ##

This project is under license from me.

Contributor: <a href="https://github.com/wutchara" target="_blank">Wutchara</a>

&#xa0;

<a href="#top">Back to top</a>